Workbook

Sheet Parameters
A1: Parameter | B1: Value | D1: Notes
A2: Speed of light c (m/s) | B2: 299792458 | D2: Source: user's ten COMSOL-exported Excel files
A3: Blood healthy RI | B3: 1.376 | D3: Final frequency grid used: 0.8–3.2 THz in 0.2 THz steps
A4: Blood cancer RI | B4: 1.39 | D4: The duplicate 'lambda' column in source files is intentionally ignored.
A5: Breast1 healthy RI | B5: 1.385 | D5: Birefringence, EML, and y-polarized analysis are outside the finalized scope.
A6: Breast1 cancer RI | B6: 1.399
A7: Breast2 healthy RI | B7: 1.387
A8: Breast2 cancer RI | B8: 1.401
A9: Cervical healthy RI | B9: 1.368
A10: Cervical cancer RI | B10: 1.392
A11: Skin healthy RI | B11: 1.36
A12: Skin cancer RI | B12: 1.38
A13: THz to Hz factor | B13: 1000000000000

Sheet Master_Data
A1: Cell type | B1: Status | C1: RI | D1: Frequency (THz) | E1: Re(neff) | F1: Im(neff) | G1: Pcore (W) | H1: Ptotal (W) | I1: Aeff (m^2) | J1: Pfrac | K1: TPF (%) | L1: RS (%) | M1: CL (dB/m) | N1: NA
A2: Blood | B2: Healthy | C2: 1.376 | D2: 0.8 | E2: 1.2699 | F2: -6.6189e-08 | G2: 5.8526e-08 | H2: 7.5479e-08 | I2: 1.2606e-07 | J2: =G2/H2 -> 0.77539448 | K2: =J2*100 -> 77.539448 | L2: =C2/E2*J2*100 -> 84.01786 | M2: =8.686*(2*PI()*(D2*Parameters!$B$13)/Parameters!$B$2)*ABS(F2) -> 0.0096395064 | N2: =1/SQRT(1+PI()*I2*((D2*Parameters!$B$13)/Parameters!$B$2)^2) -> 0.51163728
A3: Blood | B3: Healthy | C3: 1.376 | D3: 1 | E3: 1.3045 | F3: -4.2258e-10 | G3: 8.2343e-08 | H3: 9.9542e-08 | I3: 1.0749e-07 | J3: =G3/H3 -> 0.82721866 | K3: =J3*100 -> 82.721866 | L3: =C3/E3*J3*100 -> 87.255874 | M3: =8.686*(2*PI()*(D3*Parameters!$B$13)/Parameters!$B$2)*ABS(F3) -> 7.6928618e-05 | N3: =1/SQRT(1+PI()*I3*((D3*Parameters!$B$13)/Parameters!$B$2)^2) -> 0.45847902
A4: Blood | B4: Healthy | C4: 1.376 | D4: 1.2 | E4: 1.3257 | F4: -4.7118e-12 | G4: 1.0944e-07 | H4: 1.2841e-07 | I4: 9.9739e-08 | J4: =G4/H4 -> 0.85227007 | K4: =J4*100 -> 85.227007 | L4: =C4/E4*J4*100 -> 88.460709 | M4: =8.686*(2*PI()*(D4*Parameters!$B$13)/Parameters!$B$2)*ABS(F4) -> 1.0293121e-06 | N4: =1/SQRT(1+PI()*I4*((D4*Parameters!$B$13)/Parameters!$B$2)^2) -> 0.40755695
A5: Blood | B5: Healthy | C5: 1.376 | D5: 1.4 | E5: 1.3396 | F5: -9.8654e-14 | G5: 1.3818e-07 | H5: 1.5996e-07 | I5: 9.663e-08 | J5: =G5/H5 -> 0.86384096 | K5: =J5*100 -> 86.384096 | L5: =C5/E5*J5*100 -> 88.73135 | M5: =8.686*(2*PI()*(D5*Parameters!$B$13)/Parameters!$B$2)*ABS(F5) -> 2.5143268e-08 | N5: =1/SQRT(1+PI()*I5*((D5*Parameters!$B$13)/Parameters!$B$2)^2) -> 0.36225506
A6: Blood | B6: Healthy | C6: 1.376 | D6: 1.6 | E6: 1.3493 | F6: -3.8045e-15 | G6: 1.6656e-07 | H6: 1.9209e-07 | I6: 9.6165e-08 | J6: =G6/H6 -> 0.86709355 | K6: =J6*100 -> 86.709355 | L6: =C6/E6*J6*100 -> 88.425163 | M6: =8.686*(2*PI()*(D6*Parameters!$B$13)/Parameters!$B$2)*ABS(F6) -> 1.1081449e-09 | N6: =1/SQRT(1+PI()*I6*((D6*Parameters!$B$13)/Parameters!$B$2)^2) -> 0.32265974
A7: Blood | B7: Healthy | C7: 1.376 | D7: 1.8 | E7: 1.3564 | F7: -2.5189e-16 | G7: 1.9217e-07 | H7: 2.2246e-07 | I7: 9.7585e-08 | J7: =G7/H7 -> 0.86384069 | K7: =J7*100 -> 86.384069 | L7: =C7/E7*J7*100 -> 87.63232 | M7: =8.686*(2*PI()*(D7*Parameters!$B$13)/Parameters!$B$2)*ABS(F7) -> 8.2539612e-11 | N7: =1/SQRT(1+PI()*I7*((D7*Parameters!$B$13)/Parameters!$B$2)^2) -> 0.28805301
A8: Blood | B8: Healthy | C8: 1.376 | D8: 2 | E8: 1.3619 | F8: 1.0697e-16 | G8: 2.1236e-07 | H8: 2.485e-07 | I8: 1.0056e-07 | J8: =G8/H8 -> 0.8545674 | K8: =J8*100 -> 85.45674 | L8: =C8/E8*J8*100 -> 86.34149 | M8: =8.686*(2*PI()*(D8*Parameters!$B$13)/Parameters!$B$2)*ABS(F8) -> 3.8946728e-11 | N8: =1/SQRT(1+PI()*I8*((D8*Parameters!$B$13)/Parameters!$B$2)^2) -> 0.25768171
A9: Blood | B9: Healthy | C9: 1.376 | D9: 2.2 | E9: 1.3664 | F9: 1.619e-15 | G9: 2.2459e-07 | H9: 2.6778e-07 | I9: 1.0482e-07 | J9: =G9/H9 -> 0.83871088 | K9: =J9*100 -> 83.871088 | L9: =C9/E9*J9*100 -> 84.460346 | M9: =8.686*(2*PI()*(D9*Parameters!$B$13)/Parameters!$B$2)*ABS(F9) -> 6.4840823e-10 | N9: =1/SQRT(1+PI()*I9*((D9*Parameters!$B$13)/Parameters!$B$2)^2) -> 0.2310409
A10: Blood | B10: Healthy | C10: 1.376 | D10: 2.4 | E10: 1.3703 | F10: 2.0329e-16 | G10: 2.2705e-07 | H10: 2.7861e-07 | I10: 1.0972e-07 | J10: =G10/H10 -> 0.81493844 | K10: =J10*100 -> 81.493844 | L10: =C10/E10*J10*100 -> 81.832832 | M10: =8.686*(2*PI()*(D10*Parameters!$B$13)/Parameters!$B$2)*ABS(F10) -> 8.8819075e-11 | N10: =1/SQRT(1+PI()*I10*((D10*Parameters!$B$13)/Parameters!$B$2)^2) -> 0.20810282
A11: Blood | B11: Healthy | C11: 1.376 | D11: 2.6 | E11: 1.3739 | F11: 5.6694e-16 | G11: 2.1946e-07 | H11: 2.8083e-07 | I11: 1.1364e-07 | J11: =G11/H11 -> 0.78146922 | K11: =J11*100 -> 78.146922 | L11: =C11/E11*J11*100 -> 78.266369 | M11: =8.686*(2*PI()*(D11*Parameters!$B$13)/Parameters!$B$2)*ABS(F11) -> 2.6834249e-10 | N11: =1/SQRT(1+PI()*I11*((D11*Parameters!$B$13)/Parameters!$B$2)^2) -> 0.18948163
A12: Blood | B12: Healthy | C12: 1.376 | D12: 2.8 | E12: 1.3775 | F12: 6.8887e-17 | G12: 2.0361e-07 | H12: 2.7629e-07 | I12: 1.1361e-07 | J12: =G12/H12 -> 0.73694307 | K12: =J12*100 -> 73.694307 | L12: =C12/E12*J12*100 -> 73.614059 | M12: =8.686*(2*PI()*(D12*Parameters!$B$13)/Parameters!$B$2)*ABS(F12) -> 3.5113514e-11 | N12: =1/SQRT(1+PI()*I12*((D12*Parameters!$B$13)/Parameters!$B$2)^2) -> 0.17640651
A13: Blood | B13: Healthy | C13: 1.376 | D13: 3 | E13: 1.3811 | F13: 3.4756e-16 | G13: 1.83e-07 | H13: 2.6848e-07 | I13: 1.0686e-07 | J13: =G13/H13 -> 0.68161502 | K13: =J13*100 -> 68.161502 | L13: =C13/E13*J13*100 -> 67.909801 | M13: =8.686*(2*PI()*(D13*Parameters!$B$13)/Parameters!$B$2)*ABS(F13) -> 1.8981478e-10 | N13: =1/SQRT(1+PI()*I13*((D13*Parameters!$B$13)/Parameters!$B$2)^2) -> 0.16996198
... A131: Skin | B131: Cancerous | C131: 1.38 | D131: 3.2 | E131: 1.3876 | F131: -3.7469e-17 | G131: 1.7239e-07 | H131: 2.6926e-07 | I131: 9.8122e-08 | J131: =G131/H131 -> 0.6402362 | K131: =J131*100 -> 64.02362 | L131: =C131/E131*J131*100 -> 63.672958 | M131: =8.686*(2*PI()*(D131*Parameters!$B$13)/Parameters!$B$2)*ABS(F131) -> 2.1827353e-11 | N131: =1/SQRT(1+PI()*I131*((D131*Parameters!$B$13)/Parameters!$B$2)^2) -> 0.1663858

Sheet Pair_Discrimination
A1: Cell type | B1: Frequency (THz) | C1: Healthy Re(neff) | D1: Cancerous Re(neff) | E1: Δneff | F1: Healthy RS (%) | G1: Cancerous RS (%) | H1: ΔRS (percentage points)
A2: Blood | B2: 0.8 | C2: =Master_Data!E2 -> 1.2699 | D2: =Master_Data!E15 -> 1.281 | E2: =ABS(D2-C2) -> 0.0111 | F2: =Master_Data!L2 -> 84.01786 | G2: =Master_Data!L15 -> 85.281723 | H2: =ABS(G2-F2) -> 1.2638629
A3: Blood | B3: 1 | C3: =Master_Data!E3 -> 1.3045 | D3: =Master_Data!E16 -> 1.3164 | E3: =ABS(D3-C3) -> 0.0119 | F3: =Master_Data!L3 -> 87.255874 | G3: =Master_Data!L16 -> 88.368253 | H3: =ABS(G3-F3) -> 1.1123786
A4: Blood | B4: 1.2 | C4: =Master_Data!E4 -> 1.3257 | D4: =Master_Data!E17 -> 1.3379 | E4: =ABS(D4-C4) -> 0.0122 | F4: =Master_Data!L4 -> 88.460709 | G4: =Master_Data!L17 -> 89.567256 | H4: =ABS(G4-F4) -> 1.1065472
A5: Blood | B5: 1.4 | C5: =Master_Data!E5 -> 1.3396 | D5: =Master_Data!E18 -> 1.3519 | E5: =ABS(D5-C5) -> 0.0123 | F5: =Master_Data!L5 -> 88.73135 | G5: =Master_Data!L18 -> 89.912251 | H5: =ABS(G5-F5) -> 1.1809017
A6: Blood | B6: 1.6 | C6: =Master_Data!E6 -> 1.3493 | D6: =Master_Data!E19 -> 1.3616 | E6: =ABS(D6-C6) -> 0.0123 | F6: =Master_Data!L6 -> 88.425163 | G6: =Master_Data!L19 -> 89.758754 | H6: =ABS(G6-F6) -> 1.333591
A7: Blood | B7: 1.8 | C7: =Master_Data!E7 -> 1.3564 | D7: =Master_Data!E20 -> 1.3687 | E7: =ABS(D7-C7) -> 0.0123 | F7: =Master_Data!L7 -> 87.63232 | G7: =Master_Data!L20 -> 89.212613 | H7: =ABS(G7-F7) -> 1.5802934
A8: Blood | B8: 2 | C8: =Master_Data!E8 -> 1.3619 | D8: =Master_Data!E21 -> 1.3741 | E8: =ABS(D8-C8) -> 0.0122 | F8: =Master_Data!L8 -> 86.34149 | G8: =Master_Data!L21 -> 88.292386 | H8: =ABS(G8-F8) -> 1.9508959
A9: Blood | B9: 2.2 | C9: =Master_Data!E9 -> 1.3664 | D9: =Master_Data!E22 -> 1.3783 | E9: =ABS(D9-C9) -> 0.0119 | F9: =Master_Data!L9 -> 84.460346 | G9: =Master_Data!L22 -> 86.942668 | H9: =ABS(G9-F9) -> 2.4823211
A10: Blood | B10: 2.4 | C10: =Master_Data!E10 -> 1.3703 | D10: =Master_Data!E23 -> 1.3819 | E10: =ABS(D10-C10) -> 0.0116 | F10: =Master_Data!L10 -> 81.832832 | G10: =Master_Data!L23 -> 85.04805 | H10: =ABS(G10-F10) -> 3.215218
A11: Blood | B11: 2.6 | C11: =Master_Data!E11 -> 1.3739 | D11: =Master_Data!E24 -> 1.3851 | E11: =ABS(D11-C11) -> 0.0112 | F11: =Master_Data!L11 -> 78.266369 | G11: =Master_Data!L24 -> 82.464852 | H11: =ABS(G11-F11) -> 4.1984831
A12: Blood | B12: 2.8 | C12: =Master_Data!E12 -> 1.3775 | D12: =Master_Data!E25 -> 1.3881 | E12: =ABS(D12-C12) -> 0.0106 | F12: =Master_Data!L12 -> 73.614059 | G12: =Master_Data!L25 -> 79.015879 | H12: =ABS(G12-F12) -> 5.4018201
A13: Blood | B13: 3 | C13: =Master_Data!E13 -> 1.3811 | D13: =Master_Data!E26 -> 1.3911 | E13: =ABS(D13-C13) -> 0.01 | F13: =Master_Data!L13 -> 67.909801 | G13: =Master_Data!L26 -> 74.559754 | H13: =ABS(G13-F13) -> 6.6499524
A14: Blood | B14: 3.2 | C14: =Master_Data!E14 -> 1.3851 | D14: =Master_Data!E27 -> 1.3942 | E14: =ABS(D14-C14) -> 0.0091 | F14: =Master_Data!L14 -> 61.506935 | G14: =Master_Data!L27 -> 69.116894 | H14: =ABS(G14-F14) -> 7.6099586
A15: Breast type 1 | B15: 0.8 | C15: =Master_Data!E28 -> 1.277 | D15: =Master_Data!E41 -> 1.2883 | E15: =ABS(D15-C15) -> 0.0113 | F15: =Master_Data!L28 -> 84.838984 | G15: =Master_Data!L41 -> 86.05092 | H15: =ABS(G15-F15) -> 1.2119359
A16: Breast type 1 | B16: 1 | C16: =Master_Data!E29 -> 1.3121 | D16: =Master_Data!E42 -> 1.324 | E16: =ABS(D16-C16) -> 0.0119 | F16: =Master_Data!L29 -> 87.981901 | G16: =Master_Data!L42 -> 89.052956 | H16: =ABS(G16-F16) -> 1.0710547
A17: Breast type 1 | B17: 1.2 | C17: =Master_Data!E30 -> 1.3335 | D17: =Master_Data!E43 -> 1.3458 | E17: =ABS(D17-C17) -> 0.0123 | F17: =Master_Data!L30 -> 89.1856 | G17: =Master_Data!L43 -> 90.222638 | H17: =ABS(G17-F17) -> 1.0370383
A18: Breast type 1 | B18: 1.4 | C18: =Master_Data!E31 -> 1.3475 | D18: =Master_Data!E44 -> 1.3599 | E18: =ABS(D18-C18) -> 0.0124 | F18: =Master_Data!L31 -> 89.503598 | G18: =Master_Data!L44 -> 90.611486 | H18: =ABS(G18-F18) -> 1.1078878
A19: Breast type 1 | B19: 1.6 | C19: =Master_Data!E32 -> 1.3572 | D19: =Master_Data!E45 -> 1.3696 | E19: =ABS(D19-C19) -> 0.0124 | F19: =Master_Data!L32 -> 89.29686 | G19: =Master_Data!L45 -> 90.539967 | H19: =ABS(G19-F19) -> 1.2431068
A20: Breast type 1 | B20: 1.8 | C20: =Master_Data!E33 -> 1.3643 | D20: =Master_Data!E46 -> 1.3767 | E20: =ABS(D20-C20) -> 0.0124 | F20: =Master_Data!L33 -> 88.673618 | G20: =Master_Data!L46 -> 90.126589 | H20: =ABS(G20-F20) -> 1.4529706
A21: Breast type 1 | B21: 2 | C21: =Master_Data!E34 -> 1.3697 | D21: =Master_Data!E47 -> 1.382 | E21: =ABS(D21-C21) -> 0.0123 | F21: =Master_Data!L34 -> 87.628217 | G21: =Master_Data!L47 -> 89.400673 | H21: =ABS(G21-F21) -> 1.7724558
A22: Breast type 1 | B22: 2.2 | C22: =Master_Data!E35 -> 1.3741 | D22: =Master_Data!E48 -> 1.3862 | E22: =ABS(D22-C22) -> 0.0121 | F22: =Master_Data!L35 -> 86.098197 | G22: =Master_Data!L48 -> 88.320524 | H22: =ABS(G22-F22) -> 2.2223269
A23: Breast type 1 | B23: 2.4 | C23: =Master_Data!E36 -> 1.3777 | D23: =Master_Data!E49 -> 1.3896 | E23: =ABS(D23-C23) -> 0.0119 | F23: =Master_Data!L36 -> 83.965288 | G23: =Master_Data!L49 -> 86.821668 | H23: =ABS(G23-F23) -> 2.8563797
A24: Breast type 1 | B24: 2.6 | C24: =Master_Data!E37 -> 1.3811 | D24: =Master_Data!E50 -> 1.3926 | E24: =ABS(D24-C24) -> 0.0115 | F24: =Master_Data!L37 -> 81.049371 | G24: =Master_Data!L50 -> 84.771977 | H24: =ABS(G24-F24) -> 3.7226056
A25: Breast type 1 | B25: 2.8 | C25: =Master_Data!E38 -> 1.3842 | D25: =Master_Data!E51 -> 1.3953 | E25: =ABS(D25-C25) -> 0.0111 | F25: =Master_Data!L38 -> 77.184 | G25: =Master_Data!L51 -> 82.024452 | H25: =ABS(G25-F25) -> 4.8404522
A26: Breast type 1 | B26: 3 | C26: =Master_Data!E39 -> 1.3874 | D26: =Master_Data!E52 -> 1.398 | E26: =ABS(D26-C26) -> 0.0106 | F26: =Master_Data!L39 -> 72.258358 | G26: =Master_Data!L52 -> 78.413103 | H26: =ABS(G26-F26) -> 6.1547449
A27: Breast type 1 | B27: 3.2 | C27: =Master_Data!E40 -> 1.3908 | D27: =Master_Data!E53 -> 1.4006 | E27: =ABS(D27-C27) -> 0.0098 | F27: =Master_Data!L40 -> 66.401638 | G27: =Master_Data!L53 -> 73.837835 | H27: =ABS(G27-F27) -> 7.4361968
A28: Breast type 2 | B28: 0.8 | C28: =Master_Data!E54 -> 1.2786 | D28: =Master_Data!E67 -> 1.2899 | E28: =ABS(D28-C28) -> 0.0113 | F28: =Master_Data!L54 -> 85.01719 | G28: =Master_Data!L67 -> 86.219731 | H28: =ABS(G28-F28) -> 1.2025415
A29: Breast type 2 | B29: 1 | C29: =Master_Data!E55 -> 1.3138 | D29: =Master_Data!E68 -> 1.3258 | E29: =ABS(D29-C29) -> 0.012 | F29: =Master_Data!L55 -> 88.139435 | G29: =Master_Data!L68 -> 89.194015 | H29: =ABS(G29-F29) -> 1.0545797
A30: Breast type 2 | B30: 1.2 | C30: =Master_Data!E56 -> 1.3353 | D30: =Master_Data!E69 -> 1.3475 | E30: =ABS(D30-C30) -> 0.0122 | F30: =Master_Data!L56 -> 89.338586 | G30: =Master_Data!L69 -> 90.36732 | H30: =ABS(G30-F30) -> 1.028734
A31: Breast type 2 | B31: 1.4 | C31: =Master_Data!E57 -> 1.3493 | D31: =Master_Data!E70 -> 1.3617 | E31: =ABS(D31-C31) -> 0.0124 | F31: =Master_Data!L57 -> 89.660198 | G31: =Master_Data!L70 -> 90.758365 | H31: =ABS(G31-F31) -> 1.0981667
A32: Breast type 2 | B32: 1.6 | C32: =Master_Data!E58 -> 1.359 | D32: =Master_Data!E71 -> 1.3714 | E32: =ABS(D32-C32) -> 0.0124 | F32: =Master_Data!L58 -> 89.482187 | G32: =Master_Data!L71 -> 90.706713 | H32: =ABS(G32-F32) -> 1.2245259
A33: Breast type 2 | B33: 1.8 | C33: =Master_Data!E59 -> 1.366 | D33: =Master_Data!E72 -> 1.3784 | E33: =ABS(D33-C33) -> 0.0124 | F33: =Master_Data!L59 -> 88.896585 | G33: =Master_Data!L72 -> 90.326425 | H33: =ABS(G33-F33) -> 1.4298402
A34: Breast type 2 | B34: 2 | C34: =Master_Data!E60 -> 1.3714 | D34: =Master_Data!E73 -> 1.3838 | E34: =ABS(D34-C34) -> 0.0124 | F34: =Master_Data!L60 -> 87.902464 | G34: =Master_Data!L73 -> 89.62964 | H34: =ABS(G34-F34) -> 1.7271754
A35: Breast type 2 | B35: 2.2 | C35: =Master_Data!E61 -> 1.3758 | D35: =Master_Data!E74 -> 1.3879 | E35: =ABS(D35-C35) -> 0.0121 | F35: =Master_Data!L61 -> 86.44101 | G35: =Master_Data!L74 -> 88.611558 | H35: =ABS(G35-F35) -> 2.1705481
A36: Breast type 2 | B36: 2.4 | C36: =Master_Data!E62 -> 1.3794 | D36: =Master_Data!E75 -> 1.3914 | E36: =ABS(D36-C36) -> 0.012 | F36: =Master_Data!L62 -> 84.404412 | G36: =Master_Data!L75 -> 87.180518 | H36: =ABS(G36-F36) -> 2.7761052
A37: Breast type 2 | B37: 2.6 | C37: =Master_Data!E63 -> 1.3827 | D37: =Master_Data!E76 -> 1.3943 | E37: =ABS(D37-C37) -> 0.0116 | F37: =Master_Data!L63 -> 81.623809 | G37: =Master_Data!L76 -> 85.242525 | H37: =ABS(G37-F37) -> 3.6187164
A38: Breast type 2 | B38: 2.8 | C38: =Master_Data!E64 -> 1.3858 | D38: =Master_Data!E77 -> 1.397 | E38: =ABS(D38-C38) -> 0.0112 | F38: =Master_Data!L64 -> 77.926557 | G38: =Master_Data!L77 -> 82.63575 | H38: =ABS(G38-F38) -> 4.7091928
A39: Breast type 2 | B39: 3 | C39: =Master_Data!E65 -> 1.3889 | D39: =Master_Data!E78 -> 1.3995 | E39: =ABS(D39-C39) -> 0.0106 | F39: =Master_Data!L65 -> 73.191266 | G39: =Master_Data!L78 -> 79.214335 | H39: =ABS(G39-F39) -> 6.0230691
A40: Breast type 2 | B40: 3.2 | C40: =Master_Data!E66 -> 1.3921 | D40: =Master_Data!E79 -> 1.4021 | E40: =ABS(D40-C40) -> 0.01 | F40: =Master_Data!L66 -> 67.493985 | G40: =Master_Data!L79 -> 74.83669 | H40: =ABS(G40-F40) -> 7.3427042
...
